Workbook

Sheet README
A1: ASIATECH Predictive Disciplinary Risk System — SAMPLE DATASET
A3: IMPORTANT: All records are SYNTHETIC (randomly generated) for system testing and demo only. They are NOT real ASIATECH data.
A4: Replace with OSA/DPO-approved, coded (pseudonymized) records before reporting any model results (see Thesis Appendix D).
A6: Sheets
A7: student_academic_year — model dataset: one row per student-academic-year (unit of analysis), 7 pre-index features + follow-up outcome.
A8: violations — violation log (source for the features and the follow-up labels).
A9: summary — class distribution per academic year (formulas).
A11: Assumptions
A12: Index date = last day of the academic year (May 31). Follow-up window = the next academic year.
A13: Label rule (formula in risk_label): 0 follow-up violations = Low, 1 = Medium, 2 or more = High.
A14: AY 2025-2026 records have no observable follow-up year, so followup_violations and risk_label are blank (use for operational prediction only).
A15: Students who are not enrolled in the next academic year (graduated/left) are also left unlabeled.
... A18: Features use only records dated on or before the index date (no target leakage). Sanction compliance = status of the most recent prior violation.

Sheet student_academic_year
A1: record_id | B1: study_id | C1: academic_year | D1: index_date | E1: prior_violation_count | F1: violation_type | G1: recency | H1: year_level | I1: department | J1: violation_interval | K1: sanction_compliance | L1: followup_violations | M1: risk_label
A2: R-0001 | B2: S-0001 | C2: 2023-2024 | D2: 45443 | E2: 1 | F2: Minor Only | G2: >180 | H2: 1st | I2: Dept A | J2: Not Applicable | K2: Non-compliance | L2: 3 | M2: =IF(L2="","",IF(L2=0,"Low",IF(L2=1,"Medium","High"))) -> High
A3: R-0002 | B3: S-0001 | C3: 2024-2025 | D3: 45808 | E3: 4+ | F3: Mixed | G3: 91–180 | H3: 2nd | I3: Dept A | J3: >90 days | K3: Full | L3: 3 | M3: =IF(L3="","",IF(L3=0,"Low",IF(L3=1,"Medium","High"))) -> High
A4: R-0003 | B4: S-0001 | C4: 2025-2026 | D4: 46173 | E4: 4+ | F4: Mixed | G4: 31–90 | H4: 3rd | I4: Dept A | J4: >90 days | K4: Full | M4: =IF(L4="","",IF(L4=0,"Low",IF(L4=1,"Medium","High")))
A5: R-0004 | B5: S-0002 | C5: 2023-2024 | D5: 45443 | E5: 1 | F5: Minor Only | G5: >180 | H5: 4th | I5: Dept D | J5: Not Applicable | K5: Non-compliance | M5: =IF(L5="","",IF(L5=0,"Low",IF(L5=1,"Medium","High")))
A6: R-0005 | B6: S-0003 | C6: 2023-2024 | D6: 45443 | E6: 1 | F6: Major Only | G6: >180 | H6: 4th | I6: Dept A | J6: Not Applicable | K6: Partial | M6: =IF(L6="","",IF(L6=0,"Low",IF(L6=1,"Medium","High")))
A7: R-0006 | B7: S-0004 | C7: 2023-2024 | D7: 45443 | E7: 2–3 | F7: Minor Only | G7: 91–180 | H7: 3rd | I7: Dept D | J7: >90 days | K7: Full | L7: 2 | M7: =IF(L7="","",IF(L7=0,"Low",IF(L7=1,"Medium","High"))) -> High
A8: R-0007 | B8: S-0004 | C8: 2024-2025 | D8: 45808 | E8: 4+ | F8: Mixed | G8: 31–90 | H8: 4th | I8: Dept D | J8: >90 days | K8: Full | M8: =IF(L8="","",IF(L8=0,"Low",IF(L8=1,"Medium","High")))
A9: R-0008 | B9: S-0005 | C9: 2023-2024 | D9: 45443 | E9: 0 | F9: No prior violation | G9: No prior violation | H9: 2nd | I9: Dept C | J9: Not Applicable | K9: No sanction | L9: 0 | M9: =IF(L9="","",IF(L9=0,"Low",IF(L9=1,"Medium","High"))) -> Low
A10: R-0009 | B10: S-0005 | C10: 2024-2025 | D10: 45808 | E10: 0 | F10: No prior violation | G10: No prior violation | H10: 3rd | I10: Dept C | J10: Not Applicable | K10: No sanction | L10: 2 | M10: =IF(L10="","",IF(L10=0,"Low",IF(L10=1,"Medium","High"))) -> High
A11: R-0010 | B11: S-0005 | C11: 2025-2026 | D11: 46173 | E11: 2–3 | F11: Mixed | G11: 91–180 | H11: 4th | I11: Dept C | J11: >90 days | K11: No sanction | M11: =IF(L11="","",IF(L11=0,"Low",IF(L11=1,"Medium","High")))
A12: R-0011 | B12: S-0006 | C12: 2023-2024 | D12: 45443 | E12: 0 | F12: No prior violation | G12: No prior violation | H12: 1st | I12: Dept C | J12: Not Applicable | K12: No sanction | L12: 0 | M12: =IF(L12="","",IF(L12=0,"Low",IF(L12=1,"Medium","High"))) -> Low
A13: R-0012 | B13: S-0006 | C13: 2024-2025 | D13: 45808 | E13: 0 | F13: No prior violation | G13: No prior violation | H13: 2nd | I13: Dept C | J13: Not Applicable | K13: No sanction | L13: 0 | M13: =IF(L13="","",IF(L13=0,"Low",IF(L13=1,"Medium","High"))) -> Low
A14: R-0013 | B14: S-0006 | C14: 2025-2026 | D14: 46173 | E14: 0 | F14: No prior violation | G14: No prior violation | H14: 3rd | I14: Dept C | J14: Not Applicable | K14: No sanction | M14: =IF(L14="","",IF(L14=0,"Low",IF(L14=1,"Medium","High")))
A15: R-0014 | B15: S-0007 | C15: 2023-2024 | D15: 45443 | E15: 1 | F15: Minor Only | G15: 91–180 | H15: 3rd | I15: Dept C | J15: Not Applicable | K15: No sanction | L15: 0 | M15: =IF(L15="","",IF(L15=0,"Low",IF(L15=1,"Medium","High"))) -> Low
A16: R-0015 | B16: S-0007 | C16: 2024-2025 | D16: 45808 | E16: 1 | F16: Minor Only | G16: >180 | H16: 4th | I16: Dept C | J16: Not Applicable | K16: No sanction | M16: =IF(L16="","",IF(L16=0,"Low",IF(L16=1,"Medium","High")))
A17: R-0016 | B17: S-0008 | C17: 2023-2024 | D17: 45443 | E17: 2–3 | F17: Minor Only | G17: 91–180 | H17: 1st | I17: Dept D | J17: 30–90 | K17: Non-compliance | L17: 0 | M17: =IF(L17="","",IF(L17=0,"Low",IF(L17=1,"Medium","High"))) -> Low
A18: R-0017 | B18: S-0008 | C18: 2024-2025 | D18: 45808 | E18: 2–3 | F18: Minor Only | G18: >180 | H18: 2nd | I18: Dept D | J18: 30–90 | K18: Non-compliance | L18: 0 | M18: =IF(L18="","",IF(L18=0,"Low",IF(L18=1,"Medium","High"))) -> Low
A19: R-0018 | B19: S-0008 | C19: 2025-2026 | D19: 46173 | E19: 2–3 | F19: Minor Only | G19: >180 | H19: 3rd | I19: Dept D | J19: 30–90 | K19: Non-compliance | M19: =IF(L19="","",IF(L19=0,"Low",IF(L19=1,"Medium","High")))
A20: R-0019 | B20: S-0009 | C20: 2023-2024 | D20: 45443 | E20: 1 | F20: Minor Only | G20: 91–180 | H20: 4th | I20: Dept D | J20: Not Applicable | K20: No sanction | M20: =IF(L20="","",IF(L20=0,"Low",IF(L20=1,"Medium","High")))
A21: R-0020 | B21: S-0010 | C21: 2023-2024 | D21: 45443 | E21: 4+ | F21: Mixed | G21: 31–90 | H21: 4th | I21: Dept B | J21: 30–90 | K21: Full | M21: =IF(L21="","",IF(L21=0,"Low",IF(L21=1,"Medium","High")))
A22: R-0021 | B22: S-0011 | C22: 2023-2024 | D22: 45443 | E22: 4+ | F22: Major Only | G22: 31–90 | H22: 2nd | I22: Dept A | J22: 30–90 | K22: Full | L22: 1 | M22: =IF(L22="","",IF(L22=0,"Low",IF(L22=1,"Medium","High"))) -> Medium
A23: R-0022 | B23: S-0011 | C23: 2024-2025 | D23: 45808 | E23: 4+ | F23: Major Only | G23: >180 | H23: 3rd | I23: Dept A | J23: 30–90 | K23: Non-compliance | L23: 4 | M23: =IF(L23="","",IF(L23=0,"Low",IF(L23=1,"Medium","High"))) -> High
A24: R-0023 | B24: S-0011 | C24: 2025-2026 | D24: 46173 | E24: 4+ | F24: Mixed | G24: 91–180 | H24: 4th | I24: Dept A | J24: >90 days | K24: Non-compliance | M24: =IF(L24="","",IF(L24=0,"Low",IF(L24=1,"Medium","High")))
A25: R-0024 | B25: S-0012 | C25: 2023-2024 | D25: 45443 | E25: 1 | F25: Major Only | G25: 91–180 | H25: 2nd | I25: Dept A | J25: Not Applicable | K25: Full | L25: 2 | M25: =IF(L25="","",IF(L25=0,"Low",IF(L25=1,"Medium","High"))) -> High
A26: R-0025 | B26: S-0012 | C26: 2024-2025 | D26: 45808 | E26: 2–3 | F26: Mixed | G26: 91–180 | H26: 3rd | I26: Dept A | J26: >90 days | K26: Partial | L26: 0 | M26: =IF(L26="","",IF(L26=0,"Low",IF(L26=1,"Medium","High"))) -> Low
A27: R-0026 | B27: S-0012 | C27: 2025-2026 | D27: 46173 | E27: 2–3 | F27: Mixed | G27: >180 | H27: 4th | I27: Dept A | J27: >90 days | K27: Partial | M27: =IF(L27="","",IF(L27=0,"Low",IF(L27=1,"Medium","High")))
A28: R-0027 | B28: S-0013 | C28: 2023-2024 | D28: 45443 | E28: 1 | F28: Minor Only | G28: >180 | H28: 4th | I28: Dept C | J28: Not Applicable | K28: Non-compliance | M28: =IF(L28="","",IF(L28=0,"Low",IF(L28=1,"Medium","High")))
A29: R-0028 | B29: S-0014 | C29: 2023-2024 | D29: 45443 | E29: 2–3 | F29: Mixed | G29: 31–90 | H29: 4th | I29: Dept D | J29: >90 days | K29: Partial | M29: =IF(L29="","",IF(L29=0,"Low",IF(L29=1,"Medium","High")))
A30: R-0029 | B30: S-0015 | C30: 2023-2024 | D30: 45443 | E30: 1 | F30: Minor Only | G30: >180 | H30: 4th | I30: Dept C | J30: Not Applicable | K30: Full | M30: =IF(L30="","",IF(L30=0,"Low",IF(L30=1,"Medium","High")))
A31: R-0030 | B31: S-0016 | C31: 2023-2024 | D31: 45443 | E31: 0 | F31: No prior violation | G31: No prior violation | H31: 1st | I31: Dept D | J31: Not Applicable | K31: No sanction | L31: 0 | M31: =IF(L31="","",IF(L31=0,"Low",IF(L31=1,"Medium","High"))) -> Low
A32: R-0031 | B32: S-0016 | C32: 2024-2025 | D32: 45808 | E32: 0 | F32: No prior violation | G32: No prior violation | H32: 2nd | I32: Dept D | J32: Not Applicable | K32: No sanction | L32: 0 | M32: =IF(L32="","",IF(L32=0,"Low",IF(L32=1,"Medium","High"))) -> Low
A33: R-0032 | B33: S-0016 | C33: 2025-2026 | D33: 46173 | E33: 0 | F33: No prior violation | G33: No prior violation | H33: 3rd | I33: Dept D | J33: Not Applicable | K33: No sanction | M33: =IF(L33="","",IF(L33=0,"Low",IF(L33=1,"Medium","High")))
A34: R-0033 | B34: S-0017 | C34: 2023-2024 | D34: 45443 | E34: 2–3 | F34: Minor Only | G34: 91–180 | H34: 3rd | I34: Dept D | J34: 30–90 | K34: Non-compliance | L34: 1 | M34: =IF(L34="","",IF(L34=0,"Low",IF(L34=1,"Medium","High"))) -> Medium
A35: R-0034 | B35: S-0017 | C35: 2024-2025 | D35: 45808 | E35: 4+ | F35: Minor Only | G35: >180 | H35: 4th | I35: Dept D | J35: >90 days | K35: Full | M35: =IF(L35="","",IF(L35=0,"Low",IF(L35=1,"Medium","High")))
A36: R-0035 | B36: S-0018 | C36: 2023-2024 | D36: 45443 | E36: 1 | F36: Major Only | G36: ≤30 days | H36: 4th | I36: Dept A | J36: Not Applicable | K36: Partial | M36: =IF(L36="","",IF(L36=0,"Low",IF(L36=1,"Medium","High")))
A37: R-0036 | B37: S-0019 | C37: 2023-2024 | D37: 45443 | E37: 0 | F37: No prior violation | G37: No prior violation | H37: 3rd | I37: Dept A | J37: Not Applicable | K37: No sanction | L37: 0 | M37: =IF(L37="","",IF(L37=0,"Low",IF(L37=1,"Medium","High"))) -> Low
A38: R-0037 | B38: S-0019 | C38: 2024-2025 | D38: 45808 | E38: 0 | F38: No prior violation | G38: No prior violation | H38: 4th | I38: Dept A | J38: Not Applicable | K38: No sanction | M38: =IF(L38="","",IF(L38=0,"Low",IF(L38=1,"Medium","High")))
A39: R-0038 | B39: S-0020 | C39: 2023-2024 | D39: 45443 | E39: 1 | F39: Major Only | G39: 91–180 | H39: 3rd | I39: Dept D | J39: Not Applicable | K39: Partial | L39: 0 | M39: =IF(L39="","",IF(L39=0,"Low",IF(L39=1,"Medium","High"))) -> Low
A40: R-0039 | B40: S-0020 | C40: 2024-2025 | D40: 45808 | E40: 1 | F40: Major Only | G40: >180 | H40: 4th | I40: Dept D | J40: Not Applicable | K40: Partial | M40: =IF(L40="","",IF(L40=0,"Low",IF(L40=1,"Medium","High")))
...

Sheet violations
A1: violation_id | B1: study_id | C1: date | D1: academic_year | E1: category | F1: severity | G1: sanction_issued | H1: sanction_compliance | I1: recorded_by
A2: V-00001 | B2: S-0074 | C2: 45084 | D2: 2023-2024 | E2: Improper uniform | F2: Minor | G2: Yes | H2: Full | I2: Teacher
A3: V-00002 | B3: S-0208 | C3: 45089 | D3: 2023-2024 | E3: Tardiness | F3: Minor | G3: Yes | H3: Non-compliance | I3: OSA
A4: V-00003 | B4: S-0109 | C4: 45091 | D4: 2023-2024 | E4: Theft | F4: Major | G4: Yes | H4: Full | I4: Teacher
A5: V-00004 | B5: S-0145 | C5: 45091 | D5: 2023-2024 | E5: Improper uniform | F5: Minor | G5: Yes | H5: Non-compliance | I5: Teacher
A6: V-00005 | B6: S-0147 | C6: 45091 | D6: 2023-2024 | E6: Bullying | F6: Major | G6: Yes | H6: Full | I6: Teacher
A7: V-00006 | B7: S-0054 | C7: 45093 | D7: 2023-2024 | E7: Use of phone in class | F7: Minor | G7: Yes | H7: Non-compliance | I7: Teacher
A8: V-00007 | B8: S-0134 | C8: 45096 | D8: 2023-2024 | E8: Tardiness | F8: Minor | G8: Yes | H8: Partial | I8: OSA
A9: V-00008 | B9: S-0013 | C9: 45097 | D9: 2023-2024 | E9: Tardiness | F9: Minor | G9: Yes | H9: Non-compliance | I9: Teacher
A10: V-00009 | B10: S-0004 | C10: 45100 | D10: 2023-2024 | E10: Use of phone in class | F10: Minor | G10: Yes | H10: Full | I10: Teacher
A11: V-00010 | B11: S-0087 | C11: 45103 | D11: 2023-2024 | E11: Improper uniform | F11: Minor | G11: No | H11: No sanction | I11: Teacher
A12: V-00011 | B12: S-0140 | C12: 45104 | D12: 2023-2024 | E12: Improper uniform | F12: Minor | G12: Yes | H12: Full | I12: OSA
A13: V-00012 | B13: S-0064 | C13: 45105 | D13: 2023-2024 | E13: Tardiness | F13: Minor | G13: Yes | H13: Full | I13: Teacher
... A624: V-00623 | B624: S-0254 | C624: 46171 | D624: 2025-2026 | E624: Tardiness | F624: Minor | G624: Yes | H624: Non-compliance | I624: OSA

Sheet summary
A1: Academic year | B1: Low | C1: Medium | D1: High | E1: Unlabeled | F1: Total records
A2: 2023-2024 | B2: =COUNTIFS(student_academic_year!$C$2:$C$661,$A2,student_academic_year!$M$2:$M$661,"Low") -> 82 | C2: =COUNTIFS(student_academic_year!$C$2:$C$661,$A2,student_academic_year!$M$2:$M$661,"Medium") -> 49 | D2: =COUNTIFS(student_academic_year!$C$2:$C$661,$A2,student_academic_year!$M$2:$M$661,"High") -> 35 | E2: =COUNTIFS(student_academic_year!$C$2:$C$661,$A2,student_academic_year!$L$2:$L$661,"") -> 54 | F2: =COUNTIF(student_academic_year!$C$2:$C$661,$A2) -> 220
A3: 2024-2025 | B3: =COUNTIFS(student_academic_year!$C$2:$C$661,$A3,student_academic_year!$M$2:$M$661,"Low") -> 74 | C3: =COUNTIFS(student_academic_year!$C$2:$C$661,$A3,student_academic_year!$M$2:$M$661,"Medium") -> 44 | D3: =COUNTIFS(student_academic_year!$C$2:$C$661,$A3,student_academic_year!$M$2:$M$661,"High") -> 36 | E3: =COUNTIFS(student_academic_year!$C$2:$C$661,$A3,student_academic_year!$L$2:$L$661,"") -> 72 | F3: =COUNTIF(student_academic_year!$C$2:$C$661,$A3) -> 226
A4: 2025-2026 | B4: =COUNTIFS(student_academic_year!$C$2:$C$661,$A4,student_academic_year!$M$2:$M$661,"Low") -> 0 | C4: =COUNTIFS(student_academic_year!$C$2:$C$661,$A4,student_academic_year!$M$2:$M$661,"Medium") -> 0 | D4: =COUNTIFS(student_academic_year!$C$2:$C$661,$A4,student_academic_year!$M$2:$M$661,"High") -> 0 | E4: =COUNTIFS(student_academic_year!$C$2:$C$661,$A4,student_academic_year!$L$2:$L$661,"") -> 214 | F4: =COUNTIF(student_academic_year!$C$2:$C$661,$A4) -> 214
A5: Total | B5: =SUM(B2:B4) -> 156 | C5: =SUM(C2:C4) -> 93 | D5: =SUM(D2:D4) -> 71 | E5: =SUM(E2:E4) -> 340 | F5: =SUM(F2:F4) -> 660
A7: Violation records (all years) | B7: =COUNTA(violations!$A$2:$A$624) -> 623
